<?xml version="1.0" encoding="UTF-8"?>
<!-- =================================================================================== -->
<!-- |    This document was autogenerated by xacro from /home/davide/ros/install/dual_arm_description/share/dual_arm_description/urdf/dual_arm/dual_arm.xacro | -->
<!-- |    EDITING THIS FILE BY HAND IS NOT RECOMMENDED                                 | -->
<!-- =================================================================================== -->
<robot name="bh_robot">
   <!-- Original URDF file by Cristian C Beltran-Hernandez -->
   <!-- <xacro:my_gripper parent_link="left_arm_link_ee" gripper_name="left_gripper" /> -->
   <!-- distance 0 0 0.152 center of mass 0.004 0.004 0.085 mass 2.4 main gripper macro -->
   <!-- Macro for, well, orange -->
   <material name="Orange">
      <color rgba="1.0 0.423529411765 0.0392156862745 1.0" />
   </material>
   <!-- ros_control-plugin -->
   <gazebo>
      <plugin filename="ign_ros2_control-system" name="ign_ros2_control::IgnitionROS2ControlPlugin">
         <parameters>/home/davide/ros/install/lbr_description/share/lbr_description/ros2_control/lbr_controllers.yaml</parameters>
         <ros>
            <namespace>/left_arm</namespace>
         </ros>
      </plugin>
   </gazebo>
   <gazebo reference="left_arm_link_0">
      <mu1>0.2</mu1>
      <mu2>0.2</mu2>
   </gazebo>
   <gazebo reference="left_arm_A1">
      <implicitSpringDamper>true</implicitSpringDamper>
      <provideFeedback>true</provideFeedback>
   </gazebo>
   <gazebo reference="left_arm_link_1">
      <mu1>0.2</mu1>
      <mu2>0.2</mu2>
   </gazebo>
   <gazebo reference="left_arm_A2">
      <implicitSpringDamper>true</implicitSpringDamper>
      <provideFeedback>true</provideFeedback>
   </gazebo>
   <gazebo reference="left_arm_link_2">
      <mu1>0.2</mu1>
      <mu2>0.2</mu2>
   </gazebo>
   <gazebo reference="left_arm_A3">
      <implicitSpringDamper>true</implicitSpringDamper>
      <provideFeedback>true</provideFeedback>
   </gazebo>
   <gazebo reference="left_arm_link_3">
      <mu1>0.2</mu1>
      <mu2>0.2</mu2>
   </gazebo>
   <gazebo reference="left_arm_A4">
      <implicitSpringDamper>true</implicitSpringDamper>
      <provideFeedback>true</provideFeedback>
   </gazebo>
   <gazebo reference="left_arm_link_4">
      <mu1>0.2</mu1>
      <mu2>0.2</mu2>
   </gazebo>
   <gazebo reference="left_arm_A5">
      <implicitSpringDamper>true</implicitSpringDamper>
      <provideFeedback>true</provideFeedback>
   </gazebo>
   <gazebo reference="left_arm_link_5">
      <mu1>0.2</mu1>
      <mu2>0.2</mu2>
   </gazebo>
   <gazebo reference="left_arm_A6">
      <implicitSpringDamper>true</implicitSpringDamper>
      <provideFeedback>true</provideFeedback>
   </gazebo>
   <gazebo reference="left_arm_link_6">
      <mu1>0.2</mu1>
      <mu2>0.2</mu2>
   </gazebo>
   <gazebo reference="left_arm_A7">
      <implicitSpringDamper>true</implicitSpringDamper>
      <provideFeedback>true</provideFeedback>
   </gazebo>
   <gazebo reference="left_arm_link_7">
      <mu1>0.2</mu1>
      <mu2>0.2</mu2>
   </gazebo>
   <ros2_control name="left_arm_system_interface" type="system">
      <hardware>
         <plugin>mock_components/GenericSystem</plugin>
      </hardware>
      <sensor name="auxiliary_sensor">
         <!-- see KUKA::FRI::LBRState -->
         <state_interface name="sample_time" />
         <state_interface name="session_state" />
         <state_interface name="connection_quality" />
         <state_interface name="safety_state" />
         <state_interface name="operation_mode" />
         <state_interface name="drive_state" />
         <state_interface name="client_command_mode" />
         <state_interface name="overlay_type" />
         <state_interface name="control_mode" />
         <state_interface name="time_stamp_sec" />
         <state_interface name="time_stamp_nano_sec" />
         <state_interface name="tracking_performance" />
      </sensor>
      <joint name="left_arm_A1">
         <command_interface name="position">
            <param name="min">-2.8797932657906435</param>
            <param name="max">2.8797932657906435</param>
         </command_interface>
         <command_interface name="effort">
            <param name="min">-200</param>
            <param name="max">200</param>
         </command_interface>
         <state_interface name="position" />
         <state_interface name="velocity" />
         <state_interface name="effort" />
      </joint>
      <joint name="left_arm_A2">
         <command_interface name="position">
            <param name="min">-2.007128639793479</param>
            <param name="max">2.007128639793479</param>
         </command_interface>
         <command_interface name="effort">
            <param name="min">-200</param>
            <param name="max">200</param>
         </command_interface>
         <state_interface name="position" />
         <state_interface name="velocity" />
         <state_interface name="effort" />
      </joint>
      <joint name="left_arm_A3">
         <command_interface name="position">
            <param name="min">-2.8797932657906435</param>
            <param name="max">2.8797932657906435</param>
         </command_interface>
         <command_interface name="effort">
            <param name="min">-200</param>
            <param name="max">200</param>
         </command_interface>
         <state_interface name="position" />
         <state_interface name="velocity" />
         <state_interface name="effort" />
      </joint>
      <joint name="left_arm_A4">
         <command_interface name="position">
            <param name="min">-2.007128639793479</param>
            <param name="max">2.007128639793479</param>
         </command_interface>
         <command_interface name="effort">
            <param name="min">-200</param>
            <param name="max">200</param>
         </command_interface>
         <state_interface name="position" />
         <state_interface name="velocity" />
         <state_interface name="effort" />
      </joint>
      <joint name="left_arm_A5">
         <command_interface name="position">
            <param name="min">-2.8797932657906435</param>
            <param name="max">2.8797932657906435</param>
         </command_interface>
         <command_interface name="effort">
            <param name="min">-200</param>
            <param name="max">200</param>
         </command_interface>
         <state_interface name="position" />
         <state_interface name="velocity" />
         <state_interface name="effort" />
      </joint>
      <joint name="left_arm_A6">
         <command_interface name="position">
            <param name="min">-2.007128639793479</param>
            <param name="max">2.007128639793479</param>
         </command_interface>
         <command_interface name="effort">
            <param name="min">-200</param>
            <param name="max">200</param>
         </command_interface>
         <state_interface name="position" />
         <state_interface name="velocity" />
         <state_interface name="effort" />
      </joint>
      <joint name="left_arm_A7">
         <command_interface name="position">
            <param name="min">-2.9146998508305306</param>
            <param name="max">2.9146998508305306</param>
         </command_interface>
         <command_interface name="effort">
            <param name="min">-200</param>
            <param name="max">200</param>
         </command_interface>
         <state_interface name="position" />
         <state_interface name="velocity" />
         <state_interface name="effort" />
      </joint>
   </ros2_control>
   <link name="left_arm_link_0">
      <inertial>
         <origin rpy="0 0 0" xyz="-0.012857 0.0 0.069964" />
         <mass value="4.855658" />
         <inertia ixx="0.017839" ixy="0.0" ixz="0.000781" iyy="0.022294" iyz="0.0" izz="0.021334" />
      </inertial>
      <visual>
         <origin rpy="0 0 0" xyz="0 0 0" />
         <geometry>
            <mesh filename="package://lbr_description/meshes/iiwa7/visual/link_0.dae" />
         </geometry>
      </visual>
      <collision>
         <origin rpy="0 0 0" xyz="0 0 0" />
         <geometry>
            <mesh filename="package://lbr_description/meshes/iiwa7/collision/link_0.stl" />
         </geometry>
      </collision>
   </link>
   <joint name="left_arm_A1" type="revolute">
      <origin rpy="0 0 0" xyz="0.0 0.0 0.1475" />
      <parent link="left_arm_link_0" />
      <child link="left_arm_link_1" />
      <axis xyz="0.0 0.0 1.0" />
      <limit effort="200" lower="-2.8797932657906435" upper="2.8797932657906435" velocity="1.710422666954443" />
      <dynamics damping="10.0" friction="0.1" />
   </joint>
   <link name="left_arm_link_1">
      <inertial>
         <origin rpy="0 0 0" xyz="0.0 -0.034819 0.123299" />
         <mass value="3.394011" />
         <inertia ixx="0.021383" ixy="0.0" ixz="0.0" iyy="0.020403" iyz="0.003797" izz="0.007563" />
      </inertial>
      <visual>
         <origin rpy="0 0 0" xyz="0.0 0.0 -0.1475" />
         <geometry>
            <mesh filename="package://lbr_description/meshes/iiwa7/visual/link_1.dae" />
         </geometry>
      </visual>
      <collision>
         <origin rpy="0 0 0" xyz="0.0 0.0 -0.1475" />
         <geometry>
            <mesh filename="package://lbr_description/meshes/iiwa7/collision/link_1.stl" />
         </geometry>
      </collision>
   </link>
   <joint name="left_arm_A2" type="revolute">
      <origin rpy="0 0 0" xyz="0.0 -0.0105 0.1925" />
      <parent link="left_arm_link_1" />
      <child link="left_arm_link_2" />
      <axis xyz="0.0 1.0 0.0" />
      <limit effort="200" lower="-2.007128639793479" upper="2.007128639793479" velocity="1.710422666954443" />
      <dynamics damping="10.0" friction="0.1" />
   </joint>
   <link name="left_arm_link_2">
      <inertial>
         <origin rpy="0 0 0" xyz="0.0 0.039793 0.086944" />
         <mass value="4.031991" />
         <inertia ixx="0.031697" ixy="0.0" ixz="0.0" iyy="0.03008" iyz="0.005889" izz="0.009666" />
      </inertial>
      <visual>
         <origin rpy="0 0 0" xyz="0.0 0.0105 -0.34" />
         <geometry>
            <mesh filename="package://lbr_description/meshes/iiwa7/visual/link_2.dae" />
         </geometry>
      </visual>
      <collision>
         <origin rpy="0 0 0" xyz="0.0 0.0105 -0.34" />
         <geometry>
            <mesh filename="package://lbr_description/meshes/iiwa7/collision/link_2.stl" />
         </geometry>
      </collision>
   </link>
   <joint name="left_arm_A3" type="revolute">
      <origin rpy="0 0 0" xyz="0.0 0.0105 0.2075" />
      <parent link="left_arm_link_2" />
      <child link="left_arm_link_3" />
      <axis xyz="0.0 0.0 1.0" />
      <limit effort="200" lower="-2.8797932657906435" upper="2.8797932657906435" velocity="1.7453292519943295" />
      <dynamics damping="10.0" friction="0.1" />
   </joint>
   <link name="left_arm_link_3">
      <inertial>
         <origin rpy="0 0 0" xyz="0.0 0.034819 0.123299" />
         <mass value="3.394011" />
         <inertia ixx="0.021383" ixy="0.0" ixz="0.0" iyy="0.020403" iyz="-0.003797" izz="0.007563" />
      </inertial>
      <visual>
         <origin rpy="0 0 0" xyz="0.0 0.0 -0.5475" />
         <geometry>
            <mesh filename="package://lbr_description/meshes/iiwa7/visual/link_3.dae" />
         </geometry>
      </visual>
      <collision>
         <origin rpy="0 0 0" xyz="0.0 0.0 -0.5475" />
         <geometry>
            <mesh filename="package://lbr_description/meshes/iiwa7/collision/link_3.stl" />
         </geometry>
      </collision>
   </link>
   <joint name="left_arm_A4" type="revolute">
      <origin rpy="0 0 0" xyz="0.0 0.0105 0.1925" />
      <parent link="left_arm_link_3" />
      <child link="left_arm_link_4" />
      <axis xyz="0.0 -1.0 0.0" />
      <limit effort="200" lower="-2.007128639793479" upper="2.007128639793479" velocity="2.2689280275926285" />
      <dynamics damping="10.0" friction="0.1" />
   </joint>
   <link name="left_arm_link_4">
      <inertial>
         <origin rpy="0 0 0" xyz="0.0 -0.039793 0.086944" />
         <mass value="4.031989" />
         <inertia ixx="0.031695" ixy="0.0" ixz="0.0" iyy="0.030079" iyz="-0.005889" izz="0.009665" />
      </inertial>
      <visual>
         <origin rpy="0 0 0" xyz="0.0 -0.0105 -0.74" />
         <geometry>
            <mesh filename="package://lbr_description/meshes/iiwa7/visual/link_4.dae" />
         </geometry>
      </visual>
      <collision>
         <origin rpy="0 0 0" xyz="0.0 -0.0105 -0.74" />
         <geometry>
            <mesh filename="package://lbr_description/meshes/iiwa7/collision/link_4.stl" />
         </geometry>
      </collision>
   </link>
   <joint name="left_arm_A5" type="revolute">
      <origin rpy="0 0 0" xyz="0.0 -0.0105 0.2075" />
      <parent link="left_arm_link_4" />
      <child link="left_arm_link_5" />
      <axis xyz="0.0 0.0 1.0" />
      <limit effort="200" lower="-2.8797932657906435" upper="2.8797932657906435" velocity="2.443460952792061" />
      <dynamics damping="10.0" friction="0.1" />
   </joint>
   <link name="left_arm_link_5">
      <inertial>
         <origin rpy="0 0 0" xyz="0.0 -0.029824 0.076267" />
         <mass value="1.529239" />
         <inertia ixx="0.008485" ixy="0.0" ixz="0.0" iyy="0.007136" iyz="0.002806" izz="0.003848" />
      </inertial>
      <visual>
         <origin rpy="0 0 0" xyz="0.0 0.0 -0.9475" />
         <geometry>
            <mesh filename="package://lbr_description/meshes/iiwa7/visual/link_5.dae" />
         </geometry>
      </visual>
      <collision>
         <origin rpy="0 0 0" xyz="0.0 0.0 -0.9475" />
         <geometry>
            <mesh filename="package://lbr_description/meshes/iiwa7/collision/link_5.stl" />
         </geometry>
      </collision>
   </link>
   <joint name="left_arm_A6" type="revolute">
      <origin rpy="0 0 0" xyz="0.0 -0.0707 0.1925" />
      <parent link="left_arm_link_5" />
      <child link="left_arm_link_6" />
      <axis xyz="0.0 1.0 0.0" />
      <limit effort="200" lower="-2.007128639793479" upper="2.007128639793479" velocity="3.141592653589793" />
      <dynamics damping="10.0" friction="0.1" />
   </joint>
   <link name="left_arm_link_6">
      <inertial>
         <origin rpy="0 0 0" xyz="0.0 0.07102 0.00495" />
         <mass value="2.403626" />
         <inertia ixx="0.007067" ixy="0.0" ixz="0.0" iyy="0.006804" iyz="0.000311" izz="0.004629" />
      </inertial>
      <visual>
         <origin rpy="0 0 0" xyz="0.0 0.0707 -1.14" />
         <geometry>
            <mesh filename="package://lbr_description/meshes/iiwa7/visual/link_6.dae" />
         </geometry>
      </visual>
      <collision>
         <origin rpy="0 0 0" xyz="0.0 0.0707 -1.14" />
         <geometry>
            <mesh filename="package://lbr_description/meshes/iiwa7/collision/link_6.stl" />
         </geometry>
      </collision>
   </link>
   <joint name="left_arm_A7" type="revolute">
      <origin rpy="0 0 0" xyz="0.0 0.0707 0.091" />
      <parent link="left_arm_link_6" />
      <child link="left_arm_link_7" />
      <axis xyz="0.0 0.0 1.0" />
      <limit effort="200" lower="-2.9146998508305306" upper="2.9146998508305306" velocity="3.141592653589793" />
      <dynamics damping="10.0" friction="0.1" />
   </joint>
   <link name="left_arm_link_7">
      <inertial>
         <origin rpy="0 0 0" xyz="3.0000e-06 -2.0000e-06 1.3782e-02" />
         <mass value="0.259474" />
         <inertia ixx="0.000171" ixy="0.0" ixz="0.0" iyy="0.000171" iyz="0.0" izz="0.000299" />
      </inertial>
      <visual>
         <origin rpy="0 0 0" xyz="0.0 0.0 -1.231" />
         <geometry>
            <mesh filename="package://lbr_description/meshes/iiwa7/visual/link_7.dae" />
         </geometry>
      </visual>
      <collision>
         <origin rpy="0 0 0" xyz="0.0 0.0 -1.231" />
         <geometry>
            <mesh filename="package://lbr_description/meshes/iiwa7/collision/link_7.stl" />
         </geometry>
      </collision>
   </link>
   <joint name="left_arm_joint_ee" type="fixed">
      <parent link="left_arm_link_7" />
      <child link="left_arm_link_ee" />
      <origin rpy="0 0 0" xyz="0 0 0.035" />
   </joint>
   <link name="left_arm_link_ee" />
   <!-- ros_control-plugin -->
   <gazebo>
      <plugin filename="ign_ros2_control-system" name="ign_ros2_control::IgnitionROS2ControlPlugin">
         <parameters>/home/davide/ros/install/lbr_description/share/lbr_description/ros2_control/lbr_controllers.yaml</parameters>
         <ros>
            <namespace>/right_arm</namespace>
         </ros>
      </plugin>
   </gazebo>
   <gazebo reference="right_arm_link_0">
      <mu1>0.2</mu1>
      <mu2>0.2</mu2>
   </gazebo>
   <gazebo reference="right_arm_A1">
      <implicitSpringDamper>true</implicitSpringDamper>
      <provideFeedback>true</provideFeedback>
   </gazebo>
   <gazebo reference="right_arm_link_1">
      <mu1>0.2</mu1>
      <mu2>0.2</mu2>
   </gazebo>
   <gazebo reference="right_arm_A2">
      <implicitSpringDamper>true</implicitSpringDamper>
      <provideFeedback>true</provideFeedback>
   </gazebo>
   <gazebo reference="right_arm_link_2">
      <mu1>0.2</mu1>
      <mu2>0.2</mu2>
   </gazebo>
   <gazebo reference="right_arm_A3">
      <implicitSpringDamper>true</implicitSpringDamper>
      <provideFeedback>true</provideFeedback>
   </gazebo>
   <gazebo reference="right_arm_link_3">
      <mu1>0.2</mu1>
      <mu2>0.2</mu2>
   </gazebo>
   <gazebo reference="right_arm_A4">
      <implicitSpringDamper>true</implicitSpringDamper>
      <provideFeedback>true</provideFeedback>
   </gazebo>
   <gazebo reference="right_arm_link_4">
      <mu1>0.2</mu1>
      <mu2>0.2</mu2>
   </gazebo>
   <gazebo reference="right_arm_A5">
      <implicitSpringDamper>true</implicitSpringDamper>
      <provideFeedback>true</provideFeedback>
   </gazebo>
   <gazebo reference="right_arm_link_5">
      <mu1>0.2</mu1>
      <mu2>0.2</mu2>
   </gazebo>
   <gazebo reference="right_arm_A6">
      <implicitSpringDamper>true</implicitSpringDamper>
      <provideFeedback>true</provideFeedback>
   </gazebo>
   <gazebo reference="right_arm_link_6">
      <mu1>0.2</mu1>
      <mu2>0.2</mu2>
   </gazebo>
   <gazebo reference="right_arm_A7">
      <implicitSpringDamper>true</implicitSpringDamper>
      <provideFeedback>true</provideFeedback>
   </gazebo>
   <gazebo reference="right_arm_link_7">
      <mu1>0.2</mu1>
      <mu2>0.2</mu2>
   </gazebo>
   <ros2_control name="right_arm_system_interface" type="system">
      <hardware>
         <plugin>mock_components/GenericSystem</plugin>
      </hardware>
      <sensor name="auxiliary_sensor">
         <!-- see KUKA::FRI::LBRState -->
         <state_interface name="sample_time" />
         <state_interface name="session_state" />
         <state_interface name="connection_quality" />
         <state_interface name="safety_state" />
         <state_interface name="operation_mode" />
         <state_interface name="drive_state" />
         <state_interface name="client_command_mode" />
         <state_interface name="overlay_type" />
         <state_interface name="control_mode" />
         <state_interface name="time_stamp_sec" />
         <state_interface name="time_stamp_nano_sec" />
         <state_interface name="tracking_performance" />
      </sensor>
      <joint name="right_arm_A1">
         <command_interface name="position">
            <param name="min">-2.8797932657906435</param>
            <param name="max">2.8797932657906435</param>
         </command_interface>
         <command_interface name="effort">
            <param name="min">-200</param>
            <param name="max">200</param>
         </command_interface>
         <state_interface name="position" />
         <state_interface name="velocity" />
         <state_interface name="effort" />
      </joint>
      <joint name="right_arm_A2">
         <command_interface name="position">
            <param name="min">-2.007128639793479</param>
            <param name="max">2.007128639793479</param>
         </command_interface>
         <command_interface name="effort">
            <param name="min">-200</param>
            <param name="max">200</param>
         </command_interface>
         <state_interface name="position" />
         <state_interface name="velocity" />
         <state_interface name="effort" />
      </joint>
      <joint name="right_arm_A3">
         <command_interface name="position">
            <param name="min">-2.8797932657906435</param>
            <param name="max">2.8797932657906435</param>
         </command_interface>
         <command_interface name="effort">
            <param name="min">-200</param>
            <param name="max">200</param>
         </command_interface>
         <state_interface name="position" />
         <state_interface name="velocity" />
         <state_interface name="effort" />
      </joint>
      <joint name="right_arm_A4">
         <command_interface name="position">
            <param name="min">-2.007128639793479</param>
            <param name="max">2.007128639793479</param>
         </command_interface>
         <command_interface name="effort">
            <param name="min">-200</param>
            <param name="max">200</param>
         </command_interface>
         <state_interface name="position" />
         <state_interface name="velocity" />
         <state_interface name="effort" />
      </joint>
      <joint name="right_arm_A5">
         <command_interface name="position">
            <param name="min">-2.8797932657906435</param>
            <param name="max">2.8797932657906435</param>
         </command_interface>
         <command_interface name="effort">
            <param name="min">-200</param>
            <param name="max">200</param>
         </command_interface>
         <state_interface name="position" />
         <state_interface name="velocity" />
         <state_interface name="effort" />
      </joint>
      <joint name="right_arm_A6">
         <command_interface name="position">
            <param name="min">-2.007128639793479</param>
            <param name="max">2.007128639793479</param>
         </command_interface>
         <command_interface name="effort">
            <param name="min">-200</param>
            <param name="max">200</param>
         </command_interface>
         <state_interface name="position" />
         <state_interface name="velocity" />
         <state_interface name="effort" />
      </joint>
      <joint name="right_arm_A7">
         <command_interface name="position">
            <param name="min">-2.9146998508305306</param>
            <param name="max">2.9146998508305306</param>
         </command_interface>
         <command_interface name="effort">
            <param name="min">-200</param>
            <param name="max">200</param>
         </command_interface>
         <state_interface name="position" />
         <state_interface name="velocity" />
         <state_interface name="effort" />
      </joint>
   </ros2_control>
   <link name="right_arm_link_0">
      <inertial>
         <origin rpy="0 0 0" xyz="-0.012857 0.0 0.069964" />
         <mass value="4.855658" />
         <inertia ixx="0.017839" ixy="0.0" ixz="0.000781" iyy="0.022294" iyz="0.0" izz="0.021334" />
      </inertial>
      <visual>
         <origin rpy="0 0 0" xyz="0 0 0" />
         <geometry>
            <mesh filename="package://lbr_description/meshes/iiwa7/visual/link_0.dae" />
         </geometry>
      </visual>
      <collision>
         <origin rpy="0 0 0" xyz="0 0 0" />
         <geometry>
            <mesh filename="package://lbr_description/meshes/iiwa7/collision/link_0.stl" />
         </geometry>
      </collision>
   </link>
   <joint name="right_arm_A1" type="revolute">
      <origin rpy="0 0 0" xyz="0.0 0.0 0.1475" />
      <parent link="right_arm_link_0" />
      <child link="right_arm_link_1" />
      <axis xyz="0.0 0.0 1.0" />
      <limit effort="200" lower="-2.8797932657906435" upper="2.8797932657906435" velocity="1.710422666954443" />
      <dynamics damping="10.0" friction="0.1" />
   </joint>
   <link name="right_arm_link_1">
      <inertial>
         <origin rpy="0 0 0" xyz="0.0 -0.034819 0.123299" />
         <mass value="3.394011" />
         <inertia ixx="0.021383" ixy="0.0" ixz="0.0" iyy="0.020403" iyz="0.003797" izz="0.007563" />
      </inertial>
      <visual>
         <origin rpy="0 0 0" xyz="0.0 0.0 -0.1475" />
         <geometry>
            <mesh filename="package://lbr_description/meshes/iiwa7/visual/link_1.dae" />
         </geometry>
      </visual>
      <collision>
         <origin rpy="0 0 0" xyz="0.0 0.0 -0.1475" />
         <geometry>
            <mesh filename="package://lbr_description/meshes/iiwa7/collision/link_1.stl" />
         </geometry>
      </collision>
   </link>
   <joint name="right_arm_A2" type="revolute">
      <origin rpy="0 0 0" xyz="0.0 -0.0105 0.1925" />
      <parent link="right_arm_link_1" />
      <child link="right_arm_link_2" />
      <axis xyz="0.0 1.0 0.0" />
      <limit effort="200" lower="-2.007128639793479" upper="2.007128639793479" velocity="1.710422666954443" />
      <dynamics damping="10.0" friction="0.1" />
   </joint>
   <link name="right_arm_link_2">
      <inertial>
         <origin rpy="0 0 0" xyz="0.0 0.039793 0.086944" />
         <mass value="4.031991" />
         <inertia ixx="0.031697" ixy="0.0" ixz="0.0" iyy="0.03008" iyz="0.005889" izz="0.009666" />
      </inertial>
      <visual>
         <origin rpy="0 0 0" xyz="0.0 0.0105 -0.34" />
         <geometry>
            <mesh filename="package://lbr_description/meshes/iiwa7/visual/link_2.dae" />
         </geometry>
      </visual>
      <collision>
         <origin rpy="0 0 0" xyz="0.0 0.0105 -0.34" />
         <geometry>
            <mesh filename="package://lbr_description/meshes/iiwa7/collision/link_2.stl" />
         </geometry>
      </collision>
   </link>
   <joint name="right_arm_A3" type="revolute">
      <origin rpy="0 0 0" xyz="0.0 0.0105 0.2075" />
      <parent link="right_arm_link_2" />
      <child link="right_arm_link_3" />
      <axis xyz="0.0 0.0 1.0" />
      <limit effort="200" lower="-2.8797932657906435" upper="2.8797932657906435" velocity="1.7453292519943295" />
      <dynamics damping="10.0" friction="0.1" />
   </joint>
   <link name="right_arm_link_3">
      <inertial>
         <origin rpy="0 0 0" xyz="0.0 0.034819 0.123299" />
         <mass value="3.394011" />
         <inertia ixx="0.021383" ixy="0.0" ixz="0.0" iyy="0.020403" iyz="-0.003797" izz="0.007563" />
      </inertial>
      <visual>
         <origin rpy="0 0 0" xyz="0.0 0.0 -0.5475" />
         <geometry>
            <mesh filename="package://lbr_description/meshes/iiwa7/visual/link_3.dae" />
         </geometry>
      </visual>
      <collision>
         <origin rpy="0 0 0" xyz="0.0 0.0 -0.5475" />
         <geometry>
            <mesh filename="package://lbr_description/meshes/iiwa7/collision/link_3.stl" />
         </geometry>
      </collision>
   </link>
   <joint name="right_arm_A4" type="revolute">
      <origin rpy="0 0 0" xyz="0.0 0.0105 0.1925" />
      <parent link="right_arm_link_3" />
      <child link="right_arm_link_4" />
      <axis xyz="0.0 -1.0 0.0" />
      <limit effort="200" lower="-2.007128639793479" upper="2.007128639793479" velocity="2.2689280275926285" />
      <dynamics damping="10.0" friction="0.1" />
   </joint>
   <link name="right_arm_link_4">
      <inertial>
         <origin rpy="0 0 0" xyz="0.0 -0.039793 0.086944" />
         <mass value="4.031989" />
         <inertia ixx="0.031695" ixy="0.0" ixz="0.0" iyy="0.030079" iyz="-0.005889" izz="0.009665" />
      </inertial>
      <visual>
         <origin rpy="0 0 0" xyz="0.0 -0.0105 -0.74" />
         <geometry>
            <mesh filename="package://lbr_description/meshes/iiwa7/visual/link_4.dae" />
         </geometry>
      </visual>
      <collision>
         <origin rpy="0 0 0" xyz="0.0 -0.0105 -0.74" />
         <geometry>
            <mesh filename="package://lbr_description/meshes/iiwa7/collision/link_4.stl" />
         </geometry>
      </collision>
   </link>
   <joint name="right_arm_A5" type="revolute">
      <origin rpy="0 0 0" xyz="0.0 -0.0105 0.2075" />
      <parent link="right_arm_link_4" />
      <child link="right_arm_link_5" />
      <axis xyz="0.0 0.0 1.0" />
      <limit effort="200" lower="-2.8797932657906435" upper="2.8797932657906435" velocity="2.443460952792061" />
      <dynamics damping="10.0" friction="0.1" />
   </joint>
   <link name="right_arm_link_5">
      <inertial>
         <origin rpy="0 0 0" xyz="0.0 -0.029824 0.076267" />
         <mass value="1.529239" />
         <inertia ixx="0.008485" ixy="0.0" ixz="0.0" iyy="0.007136" iyz="0.002806" izz="0.003848" />
      </inertial>
      <visual>
         <origin rpy="0 0 0" xyz="0.0 0.0 -0.9475" />
         <geometry>
            <mesh filename="package://lbr_description/meshes/iiwa7/visual/link_5.dae" />
         </geometry>
      </visual>
      <collision>
         <origin rpy="0 0 0" xyz="0.0 0.0 -0.9475" />
         <geometry>
            <mesh filename="package://lbr_description/meshes/iiwa7/collision/link_5.stl" />
         </geometry>
      </collision>
   </link>
   <joint name="right_arm_A6" type="revolute">
      <origin rpy="0 0 0" xyz="0.0 -0.0707 0.1925" />
      <parent link="right_arm_link_5" />
      <child link="right_arm_link_6" />
      <axis xyz="0.0 1.0 0.0" />
      <limit effort="200" lower="-2.007128639793479" upper="2.007128639793479" velocity="3.141592653589793" />
      <dynamics damping="10.0" friction="0.1" />
   </joint>
   <link name="right_arm_link_6">
      <inertial>
         <origin rpy="0 0 0" xyz="0.0 0.07102 0.00495" />
         <mass value="2.403626" />
         <inertia ixx="0.007067" ixy="0.0" ixz="0.0" iyy="0.006804" iyz="0.000311" izz="0.004629" />
      </inertial>
      <visual>
         <origin rpy="0 0 0" xyz="0.0 0.0707 -1.14" />
         <geometry>
            <mesh filename="package://lbr_description/meshes/iiwa7/visual/link_6.dae" />
         </geometry>
      </visual>
      <collision>
         <origin rpy="0 0 0" xyz="0.0 0.0707 -1.14" />
         <geometry>
            <mesh filename="package://lbr_description/meshes/iiwa7/collision/link_6.stl" />
         </geometry>
      </collision>
   </link>
   <joint name="right_arm_A7" type="revolute">
      <origin rpy="0 0 0" xyz="0.0 0.0707 0.091" />
      <parent link="right_arm_link_6" />
      <child link="right_arm_link_7" />
      <axis xyz="0.0 0.0 1.0" />
      <limit effort="200" lower="-2.9146998508305306" upper="2.9146998508305306" velocity="3.141592653589793" />
      <dynamics damping="10.0" friction="0.1" />
   </joint>
   <link name="right_arm_link_7">
      <inertial>
         <origin rpy="0 0 0" xyz="3.0000e-06 -2.0000e-06 1.3782e-02" />
         <mass value="0.259474" />
         <inertia ixx="0.000171" ixy="0.0" ixz="0.0" iyy="0.000171" iyz="0.0" izz="0.000299" />
      </inertial>
      <visual>
         <origin rpy="0 0 0" xyz="0.0 0.0 -1.231" />
         <geometry>
            <mesh filename="package://lbr_description/meshes/iiwa7/visual/link_7.dae" />
         </geometry>
      </visual>
      <collision>
         <origin rpy="0 0 0" xyz="0.0 0.0 -1.231" />
         <geometry>
            <mesh filename="package://lbr_description/meshes/iiwa7/collision/link_7.stl" />
         </geometry>
      </collision>
   </link>
   <joint name="right_arm_joint_ee" type="fixed">
      <parent link="right_arm_link_7" />
      <child link="right_arm_link_ee" />
      <origin rpy="0 0 0" xyz="0 0 0.035" />
   </joint>
   <link name="right_arm_link_ee" />
   <!-- KDL requires a link without inertia -->
   <link name="bh_robot_base" />
   <joint name="steel_torso_base_joint" type="fixed">
      <parent link="bh_robot_base" />
      <child link="steel_torso_base" />
      <origin rpy="0 0 3.14159265359" xyz="0 0 0" />
   </joint>
   <joint name="steel_torso_left_joint" type="fixed">
      <parent link="steel_torso_base" />
      <child link="steel_torso_left" />
      <origin rpy="-1.01985341 -0.3007097 -0.70361386" xyz="0.065 0.1126 0.10074" />
   </joint>
   <joint name="steel_torso_right_joint" type="fixed">
      <parent link="steel_torso_base" />
      <child link="steel_torso_right" />
      <origin rpy="1.01985341 -0.3007097  0.70361386" xyz="0.065 -0.1126 0.10074" />
   </joint>
   <joint name="steel_torso_back_joint" type="fixed">
      <parent link="steel_torso_base" />
      <child link="steel_torso_back" />
      <origin rpy="1.01985341 -0.3007097 -1.39078124" xyz="-0.13 0 0.10074" />
   </joint>
   <link name="steel_torso_left" />
   <link name="steel_torso_right" />
   <link name="steel_torso_back" />
   <link name="steel_torso_base">
      <inertial>
         <origin rpy="0 0 0" xyz="0 0 0" />
         <mass value="17.097" />
         <inertia ixx="0.231426028862462" ixy="3.4651505109641E-07" ixz="9.00820316949685E-07" iyy="0.352096317978007" iyz="1.23740976421988E-05" izz="0.231751030960783" />
      </inertial>
      <visual>
         <origin rpy="0 0 0" xyz="0 0 0" />
         <geometry>
            <mesh filename="package://dual_arm_description/meshes/torso/steel_torso.stl" />
         </geometry>
         <material name="grey">
            <color rgba="0.8667 0.86667 0.8902 1" />
         </material>
      </visual>
      <!-- <collision> <origin xyz="${mount_origin}" rpy="0 0 0" /> <geometry> <mesh filename="package://bh_description/meshes/iiwa_mount/steel_torso.stl" /> </geometry> </collision> -->
   </link>
   <!--  Define the origin of your 3D space Here we define a box lying at 0,0,0 with some dimensions, in reality our robot is place on top of a metal cart with those dimensions. This will include the cart in the scene and avoid the robot to hit it when using MoveIt! If you don't want to have that you can define a basic world link (see commented lines) -->
   <joint name="footprint_joint" type="fixed">
      <parent link="steel_torso_base" />
      <child link="table_base_link" />
      <origin rpy="0 0 3.14159265359" xyz="0.186 0.4 -0.83" />
   </joint>
   <joint name="table_origin_joint" type="fixed">
      <parent link="table_base_link" />
      <child link="table_origin" />
      <origin xyz="0 0 0.83" />
   </joint>
   <!-- x 185mm from the CAD plus 1mm shift in mounting position y centered half width of the table -->
   <!-- <joint name="torso_origin_joint" type="fixed"> <parent link="table_origin"/> <child link = "torso_origin"/> <origin xyz="0.186 ${table_width/2} 0" /> </joint> -->
   <joint name="plate_1_inner_joint" type="fixed">
      <parent link="table_origin" />
      <child link="plate_1_inner" />
      <origin rpy="0 0 3.14159265359" xyz="1.4500000000000002 0.194 0.02" />
   </joint>
   <!-- commented out since they are typically not used <joint name="plate_1_outer_joint" type="fixed"> <parent link="plate_1_inner"/> <child link = "plate_1_outer"/> <origin xyz="0 0.05 0" rpy="0 0 0" /> </joint> -->
   <joint name="plate_2_inner_joint" type="fixed">
      <parent link="table_origin" />
      <child link="plate_2_inner" />
      <origin rpy="0 0 3.14159265359" xyz="1.4500000000000002 0.6060000000000001 0.02" />
   </joint>
   <!-- commented out since they are typically not used <joint name="plate_2_outer_joint" type="fixed"> <parent link="plate_2_inner"/> <child link = "plate_2_outer"/> <origin xyz="0 -0.05 0" rpy="0 0 0" /> </joint> -->
   <link name="table_origin" />
   <!-- <link name="torso_origin"> </link> -->
   <!-- commented out since they are typically not used <link name="plate_1_outer"> </link> -->
   <!-- this one is typically used -->
   <link name="plate_1_inner" />
   <!-- commented out since they are typically not used <link name="plate_2_outer"> </link> -->
   <!-- this one is typically used -->
   <link name="plate_2_inner" />
   <link name="table_base_link">
      <inertial>
         <origin rpy="0 0 0" xyz="0.8 0.4 0.415" />
         <mass value="100.0" />
         <inertia ixx="11.074162237" ixy="0.0" ixz="0.0" iyy="27.074155837000003" iyz="0.0" izz="26.666656000000007" />
      </inertial>
      <visual>
         <origin rpy="0 0 0" xyz="0.8 0.4 0.415" />
         <geometry>
            <box size="1.6 0.8 0.83" />
         </geometry>
         <material name="Orange" />
      </visual>
      <collision>
         <origin rpy="0 0 0" xyz="0.8 0.4 0.415" />
         <geometry>
            <box size="1.6 0.8 0.83" />
         </geometry>
      </collision>
   </link>
   <!-- Insert left and right arm into the corresponding position -->
   <joint name="left_arm_base" type="fixed">
      <origin rpy="0 0 0" xyz="0 0.0 0" />
      <parent link="steel_torso_left" />
      <child link="left_arm_link_0" />
   </joint>
   <joint name="right_arm_base" type="fixed">
      <origin rpy="0 0 0" xyz="0 0.0 0" />
      <parent link="steel_torso_right" />
      <child link="right_arm_link_0" />
   </joint>
   <ros2_control name="hande_left_gripper" type="system">
      <hardware>
         <plugin>robotiq_hande_driver/RobotiqHandeHardwareInterface</plugin>
         <param name="grip_pos_min">0.0</param>
         <param name="grip_pos_max">0.025</param>
         <param name="tty">/dev/ttymunin</param>
         <param name="baudrate">115200</param>
         <param name="parity">N</param>
         <param name="data_bits">8</param>
         <param name="stop_bit">1</param>
         <param name="slave_id">9</param>
      </hardware>
      <!-- The right finger joint uses the mimic feature -->
      <joint name="left_hande_robotiq_hande_left_finger_joint">
         <command_interface name="position">
            <param name="min">0</param>
            <param name="max">0.025</param>
         </command_interface>
         <state_interface name="position">
            <param name="initial_value">0.025</param>
         </state_interface>
         <state_interface name="velocity">
            <param name="initial_value">0</param>
         </state_interface>
      </joint>
   </ros2_control>
   <!-- Robotiq Hand-E specs -->
   <!--  + Height added by the IO coupler 11.0mm -->
   <!--  + Height added by the Hand-E 99.0mm -->
   <!--  + Coupler mass includes the bolts -->
   <joint name="left_hande_robotiq_hande_coupler_joint" type="fixed">
      <origin rpy="0 0 0" xyz="0 0 0" />
      <parent link="left_arm_link_ee" />
      <child link="left_hande_robotiq_hande_coupler" />
   </joint>
   <link name="left_hande_robotiq_hande_coupler">
      <visual>
         <geometry>
            <mesh filename="package://robotiq_hande_description/meshes/io_coupler.dae" />
         </geometry>
      </visual>
      <collision>
         <origin rpy="0 0 0" xyz="0 0 0.005449999999999999" />
         <geometry>
            <cylinder length="0.0169" radius="0.0385" />
         </geometry>
      </collision>
      <inertial>
         <mass value="0.119" />
         <origin rpy="0 0 0" xyz="0 0 0.005449999999999999" />
         <inertia ixx="4.4668218799372e-05" ixy="0.0" ixz="0.0" iyy="4.4668218799372e-05" iyz="0.0" izz="8.367187499999999e-05" />
      </inertial>
   </link>
   <joint name="left_hande_robotiq_hande_base_joint" type="fixed">
      <origin rpy="0 0 0" xyz="0 0 0.011" />
      <parent link="left_hande_robotiq_hande_coupler" />
      <child link="left_hande_robotiq_hande_link" />
   </joint>
   <link name="left_hande_robotiq_hande_link">
      <visual>
         <origin rpy="0 0 0" xyz="0 0 0" />
         <geometry>
            <mesh filename="package://robotiq_hande_description/meshes/hande.dae" scale="1.0 1.0 1.0" />
         </geometry>
      </visual>
      <collision>
         <origin rpy="0 0 0" xyz="0 0 0.053450000000000004" />
         <geometry>
            <cylinder length="0.10690000000000001" radius="0.0385" />
         </geometry>
      </collision>
      <inertial>
         <mass value="0.86387" />
         <origin rpy="0 0 0" xyz="0 0 0.0495" />
         <inertia ixx="0.0010092697156669523" ixy="0.0" ixz="0.0" iyy="0.0010092697156669523" iyz="0.0" izz="0.00060740859375" />
      </inertial>
   </link>
   <joint name="left_hande_robotiq_hande_left_finger_joint" type="prismatic">
      <origin rpy="0 0 0" xyz="0 0 0.099" />
      <parent link="left_hande_robotiq_hande_link" />
      <child link="left_hande_robotiq_hande_left_finger" />
      <axis xyz="1 0 0" />
      <limit effort="130" lower="0.0" upper="0.025" velocity="0.15" />
   </joint>
   <link name="left_hande_robotiq_hande_left_finger">
      <visual>
         <origin rpy="0 0 0" xyz="0 0 0" />
         <geometry>
            <mesh filename="package://robotiq_hande_description/meshes/finger.dae" scale="1.0 1.0 1.0" />
         </geometry>
      </visual>
      <collision>
         <origin rpy="0 0 0" xyz="0 0 0" />
         <geometry>
            <mesh filename="package://robotiq_hande_description/meshes/finger_collision.dae" scale="1.0 1.0 1.0" />
         </geometry>
      </collision>
      <inertial>
         <origin rpy="0 0 0" xyz="0 0 0" />
         <mass value="0.03804" />
         <inertia ixx="1E-9" ixy="0.0" ixz="0.0" iyy="1E-9" iyz="0.0" izz="1E-9" />
      </inertial>
   </link>
   <joint name="left_hande_robotiq_hande_right_finger_joint" type="prismatic">
      <origin rpy="0 0 0" xyz="0 0 0.099" />
      <parent link="left_hande_robotiq_hande_link" />
      <child link="left_hande_robotiq_hande_right_finger" />
      <axis xyz="-1 0 0" />
      <limit effort="130" lower="0.0" upper="0.025" velocity="0.15" />
      <mimic joint="left_hande_robotiq_hande_left_finger_joint" multiplier="1" offset="0" />
   </joint>
   <link name="left_hande_robotiq_hande_right_finger">
      <visual>
         <origin rpy="0 0 3.141592653589793" xyz="0 0 0" />
         <geometry>
            <mesh filename="package://robotiq_hande_description/meshes/finger.dae" scale="1.0 1.0 1.0" />
         </geometry>
      </visual>
      <collision>
         <origin rpy="0 0 3.141592653589793" xyz="0 0 0" />
         <geometry>
            <mesh filename="package://robotiq_hande_description/meshes/finger_collision.dae" scale="1.0 1.0 1.0" />
         </geometry>
      </collision>
      <inertial>
         <origin rpy="0 0 0" xyz="0 0 0" />
         <mass value="0.03804" />
         <inertia ixx="1E-9" ixy="0.0" ixz="0.0" iyy="1E-9" iyz="0.0" izz="1E-9" />
      </inertial>
   </link>
   <joint name="left_hande_robotiq_hande_end_joint" type="fixed">
      <origin rpy="0 0 0" xyz="0 0 0.14550000000000002" />
      <parent link="left_hande_robotiq_hande_link" />
      <child link="left_hande_robotiq_hande_end" />
   </joint>
   <link name="left_hande_robotiq_hande_end" />
   <ros2_control name="hande_right_gripper" type="system">
      <hardware>
         <plugin>robotiq_hande_driver/RobotiqHandeHardwareInterface</plugin>
         <param name="grip_pos_min">0.0</param>
         <param name="grip_pos_max">0.025</param>
         <param name="tty">/dev/ttyhugin</param>
         <param name="baudrate">115200</param>
         <param name="parity">N</param>
         <param name="data_bits">8</param>
         <param name="stop_bit">1</param>
         <param name="slave_id">9</param>
      </hardware>
      <!-- The right finger joint uses the mimic feature -->
      <joint name="right_hande_robotiq_hande_left_finger_joint">
         <command_interface name="position">
            <param name="min">0</param>
            <param name="max">0.025</param>
         </command_interface>
         <state_interface name="position">
            <param name="initial_value">0.025</param>
         </state_interface>
         <state_interface name="velocity">
            <param name="initial_value">0</param>
         </state_interface>
      </joint>
   </ros2_control>
   <!-- Robotiq Hand-E specs -->
   <!--  + Height added by the IO coupler 11.0mm -->
   <!--  + Height added by the Hand-E 99.0mm -->
   <!--  + Coupler mass includes the bolts -->
   <joint name="right_hande_robotiq_hande_coupler_joint" type="fixed">
      <origin rpy="0 0 0" xyz="0 0 0" />
      <parent link="right_arm_link_ee" />
      <child link="right_hande_robotiq_hande_coupler" />
   </joint>
   <link name="right_hande_robotiq_hande_coupler">
      <visual>
         <geometry>
            <mesh filename="package://robotiq_hande_description/meshes/io_coupler.dae" />
         </geometry>
      </visual>
      <collision>
         <origin rpy="0 0 0" xyz="0 0 0.005449999999999999" />
         <geometry>
            <cylinder length="0.0169" radius="0.0385" />
         </geometry>
      </collision>
      <inertial>
         <mass value="0.119" />
         <origin rpy="0 0 0" xyz="0 0 0.005449999999999999" />
         <inertia ixx="4.4668218799372e-05" ixy="0.0" ixz="0.0" iyy="4.4668218799372e-05" iyz="0.0" izz="8.367187499999999e-05" />
      </inertial>
   </link>
   <joint name="right_hande_robotiq_hande_base_joint" type="fixed">
      <origin rpy="0 0 0" xyz="0 0 0.011" />
      <parent link="right_hande_robotiq_hande_coupler" />
      <child link="right_hande_robotiq_hande_link" />
   </joint>
   <link name="right_hande_robotiq_hande_link">
      <visual>
         <origin rpy="0 0 0" xyz="0 0 0" />
         <geometry>
            <mesh filename="package://robotiq_hande_description/meshes/hande.dae" scale="1.0 1.0 1.0" />
         </geometry>
      </visual>
      <collision>
         <origin rpy="0 0 0" xyz="0 0 0.053450000000000004" />
         <geometry>
            <cylinder length="0.10690000000000001" radius="0.0385" />
         </geometry>
      </collision>
      <inertial>
         <mass value="0.86387" />
         <origin rpy="0 0 0" xyz="0 0 0.0495" />
         <inertia ixx="0.0010092697156669523" ixy="0.0" ixz="0.0" iyy="0.0010092697156669523" iyz="0.0" izz="0.00060740859375" />
      </inertial>
   </link>
   <joint name="right_hande_robotiq_hande_left_finger_joint" type="prismatic">
      <origin rpy="0 0 0" xyz="0 0 0.099" />
      <parent link="right_hande_robotiq_hande_link" />
      <child link="right_hande_robotiq_hande_left_finger" />
      <axis xyz="1 0 0" />
      <limit effort="130" lower="0.0" upper="0.025" velocity="0.15" />
   </joint>
   <link name="right_hande_robotiq_hande_left_finger">
      <visual>
         <origin rpy="0 0 0" xyz="0 0 0" />
         <geometry>
            <mesh filename="package://robotiq_hande_description/meshes/finger.dae" scale="1.0 1.0 1.0" />
         </geometry>
      </visual>
      <collision>
         <origin rpy="0 0 0" xyz="0 0 0" />
         <geometry>
            <mesh filename="package://robotiq_hande_description/meshes/finger_collision.dae" scale="1.0 1.0 1.0" />
         </geometry>
      </collision>
      <inertial>
         <origin rpy="0 0 0" xyz="0 0 0" />
         <mass value="0.03804" />
         <inertia ixx="1E-9" ixy="0.0" ixz="0.0" iyy="1E-9" iyz="0.0" izz="1E-9" />
      </inertial>
   </link>
   <joint name="right_hande_robotiq_hande_right_finger_joint" type="prismatic">
      <origin rpy="0 0 0" xyz="0 0 0.099" />
      <parent link="right_hande_robotiq_hande_link" />
      <child link="right_hande_robotiq_hande_right_finger" />
      <axis xyz="-1 0 0" />
      <limit effort="130" lower="0.0" upper="0.025" velocity="0.15" />
      <mimic joint="right_hande_robotiq_hande_left_finger_joint" multiplier="1" offset="0" />
   </joint>
   <link name="right_hande_robotiq_hande_right_finger">
      <visual>
         <origin rpy="0 0 3.141592653589793" xyz="0 0 0" />
         <geometry>
            <mesh filename="package://robotiq_hande_description/meshes/finger.dae" scale="1.0 1.0 1.0" />
         </geometry>
      </visual>
      <collision>
         <origin rpy="0 0 3.141592653589793" xyz="0 0 0" />
         <geometry>
            <mesh filename="package://robotiq_hande_description/meshes/finger_collision.dae" scale="1.0 1.0 1.0" />
         </geometry>
      </collision>
      <inertial>
         <origin rpy="0 0 0" xyz="0 0 0" />
         <mass value="0.03804" />
         <inertia ixx="1E-9" ixy="0.0" ixz="0.0" iyy="1E-9" iyz="0.0" izz="1E-9" />
      </inertial>
   </link>
   <joint name="right_hande_robotiq_hande_end_joint" type="fixed">
      <origin rpy="0 0 0" xyz="0 0 0.14550000000000002" />
      <parent link="right_hande_robotiq_hande_link" />
      <child link="right_hande_robotiq_hande_end" />
   </joint>
   <link name="right_hande_robotiq_hande_end" />
</robot>
